Workbook

Sheet TF1000cells_motifs
A1: TF | B1: n | C1: AME motif for peaks | D1: Homer motif for peaks | E1: AME motif for bins | F1: Homer motif for bins | G1: Imputed Data: AME motif for peaks | H1: Imputed Data: Homer motif for peaks | I1: Homer database | J1: HOCOMOCOv11 database | K1: Codebook database
A2: CTCF | B2: 10410 | C2: NA | D2: 1e-39 | E2: NA | F2: 1e-68 | H2: 1e-101 | I2: CTCF | J2: CTCF | K2: CTCF
A3: E2F3 | B3: 30622 | C3: 4.44e-10 | D3: 1e-64 | E3: NA | F3: 1e-85 | G3: 2.47e-06 | H3: 1e-70 | I3: E2F3 | J3: E2F3 | K3: #N/A
A4: EPAS1 | B4: 1046 | C4: NA | D4: NA | E4: NA | F4: NA | I4: #N/A | J4: EPAS1 | K4: #N/A
A5: ETS2 | B5: 1637 | C5: NA | D5: NA | E5: NA | F5: NA | I5: #N/A | J5: ETS2 | K5: #N/A
A6: FOXC1 | B6: 4760 | C6: NA | D6: NA | E6: NA | F6: NA | I6: #N/A | J6: FOXC1 | K6: #N/A
A7: FOXJ3 | B7: 2303 | C7: NA | D7: NA | E7: NA | F7: NA | I7: #N/A | J7: FOXJ3 | K7: #N/A
A8: FOXK1 | B8: 1202 | C8: NA | D8: 1 | E8: NA | F8: 1 | I8: FOXK1 | J8: FOXK1 | K8: #N/A
A9: MAZ | B9: 3968 | C9: 1.93e-12 | D9: 0.001 | E9: NA | F9: 1e-08 | I9: Maz | J9: MAZ | K9: #N/A
A10: MEF2A | B10: 1027 | C10: NA | D10: 1 | E10: NA | F10: 1 | I10: #N/A | J10: MEF2A | K10: #N/A
A11: MEF2D | B11: 1764 | C11: NA | D11: 1 | E11: NA | F11: NA | I11: Mef2d | J11: MEF2D | K11: #N/A
A12: NFYA | B12: 70292 | C12: 1.76e-14 | D12: NA | E12: NA | F12: NA | I12: #N/A | J12: NFYA | K12: #N/A
A13: NRF1 | B13: 1416 | C13: NA | D13: 1e-22 | E13: NA | F13: 1e-18 | H13: 1e-33 | I13: NRF1 | J13: NRF1 | K13: #N/A
A14: SOX4 | B14: 64652 | C14: NA | D14: 1 | E14: 1.6e-34 | F14: 1e-05 | I14: Sox4 | J14: SOX4 | K14: #N/A
A15: TBX3 | B15: 4391 | C15: NA | D15: NA | E15: NA | F15: NA | I15: #N/A | J15: TBX3 | K15: #N/A
A16: RBBP4 | B16: 181396 | C16: NA | D16: NA | F16: NA | I16: #N/A | J16: #N/A | K16: #N/A
A17: XPA | B17: 50752 | C17: NA | D17: NA | E17: NA | F17: NA | I17: #N/A | J17: #N/A | K17: #N/A
A18: RBBP7 | B18: 39619 | C18: NA | D18: NA | E18: NA | F18: NA | I18: #N/A | J18: #N/A | K18: #N/A
A19: ZNF507 | B19: 30870 | C19: NA | D19: NA | E19: NA | F19: NA | I19: #N/A | J19: #N/A | K19: ZNF507
A20: NME2 | B20: 30095 | C20: NA | D20: NA | E20: NA | F20: NA | I20: #N/A | J20: #N/A | K20: #N/A
A21: MBD3 | B21: 28330 | C21: NA | D21: NA | E21: NA | F21: NA | I21: #N/A | J21: #N/A | K21: MBD3
A22: MLX | B22: 23262 | C22: NA | D22: NA | E22: NA | F22: NA | I22: #N/A | J22: #N/A | K22: #N/A
A23: DDIT3 | B23: 22129 | C23: NA | D23: NA | E23: NA | F23: NA | I23: #N/A | J23: #N/A | K23: #N/A
A24: ZNF703 | B24: 21216 | C24: NA | D24: NA | E24: NA | F24: NA | I24: #N/A | J24: #N/A | K24: ZNF703
A25: GLYR1 | B25: 16883 | C25: NA | D25: NA | E25: NA | F25: NA | I25: #N/A | J25: #N/A | K25: GLYR1
A26: E4F1 | B26: 12061 | C26: NA | D26: NA | E26: NA | F26: NA | I26: #N/A | J26: #N/A | K26: #N/A
A27: SAFB | B27: 9654 | C27: NA | D27: NA | E27: NA | F27: NA | I27: #N/A | J27: #N/A | K27: #N/A
A28: MTF2 | B28: 8746 | C28: NA | D28: NA | E28: NA | F28: NA | I28: #N/A | J28: #N/A | K28: #N/A
A29: ZBTB7A | B29: 7005 | C29: NA | D29: 1 | E29: NA | F29: 0.0001 | I29: ZBTB7A | J29: #N/A | K29: #N/A
A30: HOXA10 | B30: 6476 | C30: NA | D30: 1 | E30: NA | F30: 0.01 | I30: #N/A | J30: #N/A | K30: #N/A
A31: HOXB9 | B31: 5903 | C31: NA | D31: NA | E31: NA | F31: NA | I31: #N/A | J31: #N/A | K31: #N/A
A32: ZNF768 | B32: 5837 | C32: NA | D32: 1 | E32: NA | F32: 1 | I32: ZNF768 | J32: #N/A | K32: #N/A
A33: FLYWCH1 | B33: 5824 | C33: NA | D33: NA | E33: NA | F33: NA | I33: #N/A | J33: #N/A | K33: FLYWCH1
A34: HOXB6 | B34: 5703 | C34: NA | D34: NA | E34: NA | F34: NA | I34: #N/A | J34: #N/A | K34: #N/A
A35: DR1 | B35: 5661 | C35: NA | D35: 0.1 | E35: NA | F35: 0.1 | I35: #N/A | J35: #N/A | K35: #N/A
A36: PA2G4 | B36: 5319 | C36: NA | D36: NA | E36: NA | F36: NA | I36: #N/A | J36: #N/A | K36: #N/A
A37: ZNF512B | B37: 5185 | C37: NA | D37: NA | E37: NA | F37: NA | I37: #N/A | J37: #N/A | K37: #N/A
A38: RBPJ | B38: 5138 | C38: NA | D38: 1 | E38: NA | F38: 0.1 | I38: #N/A | J38: #N/A | K38: #N/A
A39: ZIC2 | B39: 4896 | C39: NA | D39: 1 | E39: NA | F39: 1 | I39: Zic2 | J39: #N/A | K39: #N/A
A40: ZNF644 | B40: 4749 | C40: NA | D40: NA | E40: NA | F40: NA | I40: #N/A | J40: #N/A | K40: #N/A
...

Sheet TF1000cells_unknown_motifs
A1: TF | B1: n_cells | C1: HOMER | D1: HOCOMOCO | E1: Codebook
A2: Still no motif in HOMER / HOCOMOCOv11 / Codebook top1 (Hughes 2026)
A4: RBBP4 | B4: 181396 | C4: #N/A | D4: Missing | E4: Missing
A5: XPA | B5: 50752 | C5: #N/A | D5: Missing | E5: Missing
A6: RBBP7 | B6: 39619 | C6: #N/A | D6: Missing | E6: Missing
A7: NME2 | B7: 30095 | C7: #N/A | D7: Missing | E7: Missing
A8: SAFB | B8: 9654 | C8: #N/A | D8: Missing | E8: Missing
A9: MTF2 | B9: 8746 | C9: #N/A | D9: Missing | E9: Missing
A10: HOXB9 | B10: 5903 | C10: #N/A | D10: Missing | E10: Missing
A11: DR1 | B11: 5661 | C11: #N/A | D11: Missing | E11: Missing
A12: PA2G4 | B12: 5319 | C12: #N/A | D12: Missing | E12: Missing
A13: ZNF512B | B13: 5185 | C13: #N/A | D13: Missing | E13: Missing
A14: ZNF644 | B14: 4749 | C14: #N/A | D14: Missing | E14: Missing
A15: EZH2 | B15: 3970 | C15: #N/A | D15: Missing | E15: Missing
... A37: HOXC4 | B37: 1023 | C37: #N/A | D37: Missing | E37: Missing

Sheet Codebook_rescued_from_unknown
A1: TF | B1: n_cells | C1: Codebook motif | D1: Note
A2: Previously listed as unknown (no HOMER/HOCOMOCO); now have a Codebook top1 PWM
A4: ZNF507 | B4: 30870 | C4: ZNF507 | D4: Moved off TF1000cells_unknown_motifs
A5: MBD3 | B5: 28330 | C5: MBD3 | D5: Moved off TF1000cells_unknown_motifs
A6: ZNF703 | B6: 21216 | C6: ZNF703 | D6: Moved off TF1000cells_unknown_motifs
A7: GLYR1 | B7: 16883 | C7: GLYR1 | D7: Moved off TF1000cells_unknown_motifs
A8: FLYWCH1 | B8: 5824 | C8: FLYWCH1 | D8: Moved off TF1000cells_unknown_motifs
A9: ZNF367 | B9: 4492 | C9: ZNF367 | D9: Moved off TF1000cells_unknown_motifs
A10: ZNF746 | B10: 3099 | C10: ZNF746 | D10: Moved off TF1000cells_unknown_motifs
A11: POGK | B11: 2651 | C11: POGK | D11: Moved off TF1000cells_unknown_motifs
A12: ZBTB40 | B12: 1535 | C12: ZBTB40 | D12: Moved off TF1000cells_unknown_motifs
A13: ZNF606 | B13: 1235 | C13: ZNF606 | D13: Moved off TF1000cells_unknown_motifs
A14: ZNF503 | B14: 1050 | C14: ZNF503 | D14: Moved off TF1000cells_unknown_motifs

Sheet TF1000cells_known_motifs
A2: TF | B2: Cell Count | C2: Raw | G2: Imputed Data: Whole Genome Background | K2: Imputed Data: Open Chromatin Region Backrgound | O2: HOCOMOCOv11 database | P2: Homer database
C3: AME motif for peaks | D3: Homer motif for peaks | E3: AME motif for bins | F3: Homer motif for bins | G3: AME motif for peaks | H3: Homer motif for peaks | I3: AME motif for bins | J3: Homer motif for bins | K3: AME motif for peaks | L3: Homer motif for peaks | M3: AME motif for bins | N3: Homer motif for bins
A4: NFYA | B4: 70292 | C4: 1.76e-14 | D4: NA | E4: F | F4: NA | G4: 0.000986 | H4: 1e-13 | I4: F | J4: 1.00E-330 | K4: F | L4: NA | M4: 1.38e-12 | N4: 1e-47 | O4: A | P4: NFYA
A5: SOX4 | B5: 64652 | C5: NA | D5: F | E5: 1.6e-34 | F5: 1e-05 | G5: F | H5: F | I5: F | J5: 1e-22 | K5: F | L5: F | M5: F | N5: F | O5: B | P5: Sox4
A6: E2F3 | B6: 30622 | C6: 4.44e-10 | D6: 1e-64 | E6: F | F6: 1e-85 | G6: 2.23e-05 | H6: 1e-70 | I6: F | J6: 1e-239 | K6: 1.21e-221 | L6: 1e-05 | M6: 7.58e-10 | N6: 1e-57 | O6: A | P6: E2F3
A7: CTCF | B7: 10410 | C7: F | D7: 1e-39 | E7: F | F7: 1e-68 | G7: F | H7: 1E-101 (#4) | I7: F | J7: 1e-36 | K7: 3.32e-32 | L7: NA | M7: 6e-38 | N7: NA | O7: A | P7: CTCF
A8: ZBTB7A | B8: 7005 | C8: F | D8: F | E8: F | F8: 0.0001 | G8: F | H8: 1e-48 | I8: F | J8: 1e-99 | K8: F | L8: 1e-59 | M8: F | N8: 0.0001 | O8: A | P8: ZBTB7A
A9: HOXA10 | B9: 6476 | C9: F | D9: F | E9: F | F9: 0.01 | G9: F | H9: 1e-06 | I9: F | J9: 1e-28 | K9: F | L9: F | M9: F | N9: F | O9: C | P9: HOXA10
A10: ZNF768 | B10: 5837 | C10: F | D10: F | E10: F | F10: F | G10: F | H10: 1e-05 | I10: F | J10: F | K10: F | L10: F | M10: F | N10: F | O10: C | P10: ZNF768
A11: RBPJ | B11: 5138 | C11: F | D11: NA | E11: F | F11: NA | G11: F | H11: NA | I11: F | J11: NA | K11: F | L11: NA | M11: F | N11: NA | O11: A | P11: #N/A
A12: FOXC1 | B12: 4760 | C12: F | D12: NA | E12: F | F12: NA | G12: F | H12: NA | I12: F | J12: NA | K12: F | L12: NA | M12: F | N12: NA | O12: C | P12: #N/A
A13: TBX3 | B13: 4391 | C13: F | D13: NA | E13: F | F13: NA | G13: F | H13: NA | I13: F | J13: NA | K13: F | L13: NA | M13: F | N13: NA | O13: C | P13: #N/A
A14: MAZ | B14: 3968 | C14: 1.93e-12 | D14: 0.001 | E14: F | F14: 1e-08 | G14: F | H14: 1e-159 | I14: F | J14: 1.00E-394 | K14: F | L14: 1e-125 | M14: F | N14: 1e-22 | O14: A | P14: Maz
A15: SMARCA1 | B15: 3745 | C15: F | D15: NA | E15: F | F15: NA | G15: F | H15: NA | I15: F | J15: NA | K15: F | L15: NA | M15: F | N15: NA | O15: C | P15: #N/A
A16: HOXC9 | B16: 3331 | C16: F | D16: 0.1 | E16: F | F16: F | G16: F | H16: 0.1 | I16: F | J16: 0.1 | K16: F | L16: F | M16: F | N16: 0.1 | O16: C | P16: Hoxc9
A17: FOXJ3 | B17: 2303 | C17: F | D17: NA | E17: F | F17: NA | G17: F | H17: NA | I17: F | J17: NA | K17: F | L17: NA | M17: F | N17: NA | O17: A | P17: #N/A
A18: RELA | B18: 2123 | C18: F | D18: NA | E18: F | F18: NA | G18: F | H18: NA | I18: F | J18: NA | K18: F | L18: NA | M18: F | N18: NA | O18: A | P18: #N/A
A19: HOXB8 | B19: 1980 | C19: F | D19: NA | E19: F | F19: NA | G19: F | H19: NA | I19: F | J19: NA | K19: F | L19: NA | M19: F | N19: NA | O19: C | P19: #N/A
A20: MEF2D | B20: 1764 | C20: F | D20: F | E20: F | F20: NA | G20: 0.00432 | H20: F | I20: F | J20: 0.01 | K20: F | L20: F | M20: F | N20: F | O20: A | P20: Mef2d
A21: ZNF143 | B21: 1736 | C21: F | D21: F | E21: F | F21: F | G21: F | H21: F | I21: F | J21: F | K21: F | L21: F | M21: F | N21: F | O21: A | P21: ZNF143
A22: ETS2 | B22: 1637 | C22: F | D22: NA | E22: F | F22: NA | G22: F | H22: NA | I22: F | J22: NA | K22: F | L22: NA | M22: F | N22: NA | O22: B | P22: #N/A
A23: NRF1 | B23: 1416 | C23: F | D23: 1e-22 | E23: F | F23: 1e-18 | G23: F | H23: 1e-24 | I23: F | J23: 1e-107 | K23: 7.86e-305 | L23: F | M23: F | N23: 1e-69 | O23: A | P23: NRF1
A24: SREBF2 | B24: 1211 | C24: F | D24: NA | E24: F | F24: NA | G24: F | H24: NA | I24: F | J24: NA | K24: F | L24: NA | M24: F | N24: NA | O24: B | P24: #N/A
A25: FOXK1 | B25: 1202 | C25: F | D25: F | E25: F | F25: F | G25: F | H25: F | I25: F | J25: 1e-25 | K25: F | L25: F | M25: F | N25: F | O25: A | P25: FOXK1
A26: EPAS1 | B26: 1046 | C26: F | D26: NA | E26: F | F26: NA | G26: F | H26: NA | I26: F | J26: NA | K26: F | L26: NA | M26: 7.8e-15 | N26: NA | O26: B | P26: #N/A
A27: MEF2A | B27: 1027 | C27: F | D27: F | E27: F | F27: F | G27: F | H27: F | I27: F | J27: F | K27: F | L27: 1e-07 | M27: F | N27: F | O27: A | P27: MEF2A
A29: F= Target motif not found in results; NA= TF not present in library

Sheet TF1000cells_known_motifs (Full)
A2: TF | B2: Cell Count | C2: Raw | G2: Imputed Data: Whole Genome Background | K2: Imputed Data: Open Chromatin Region Backrgound | O2: HOCOMOCOv11 database | P2: Homer database
C3: AME motif for peaks | D3: Homer motif for peaks | E3: AME motif for bins | F3: Homer motif for bins | G3: AME motif for peaks | H3: Homer motif for peaks | I3: AME motif for bins | J3: Homer motif for bins | K3: AME motif for peaks | L3: Homer motif for peaks | M3: AME motif for bins | N3: Homer motif for bins
A4: NFYA | B4: 70292 | C4: 1.76e-14 | D4: NA | E4: F | F4: NA | G4: 0.000986 | H4: NA | I4: F | J4: NA | K4: F | L4: NA | M4: 1.38e-12 | N4: NA | O4: A | P4: #N/A
A5: SOX4 | B5: 64652 | C5: NA | D5: 1 | E5: 1.6e-34 | F5: 1e-05 | H5: 1 | I5: F | J5: 1e-22 | K5: F | L5: 1 | M5: F | N5: 1 | O5: B | P5: Sox4
A6: E2F3 | B6: 30622 | C6: 4.44e-10 | D6: 1e-64 | E6: F | F6: 1e-85 | G6: 2.23e-05 | H6: 1e-70 | I6: F | J6: 1e-239 | K6: 1.21e-221 | L6: 0.1 | M6: 7.58e-10 | N6: 1e-57 | O6: A | P6: E2F3
A7: MLX | B7: 23262 | C7: F | D7: NA | E7: F | F7: NA | G7: F | H7: NA | I7: F | J7: NA | K7: 3.32e-32 | L7: NA | M7: 6e-38 | N7: NA | O7: D | P7: #N/A
A8: DDIT3 | B8: 22129 | C8: F | D8: NA | E8: F | F8: NA | G8: 2.17e-18 | H8: NA | I8: F | J8: NA | K8: F | L8: NA | M8: F | N8: NA | O8: D | P8: #N/A
A9: E4F1 | B9: 12061 | C9: F | D9: NA | E9: F | F9: NA | G9: F | H9: NA | I9: F | J9: NA | K9: F | L9: NA | M9: 1.87e-20 | N9: NA | O9: D | P9: #N/A
A10: CTCF | B10: 10410 | C10: F | D10: 1e-39 | E10: F | F10: 1e-68 | G10: F | H10: 1e-101 | I10: F | J10: 1e-36 | K10: F | L10: 1 | M10: 1.61e-11 | N10: 1 | O10: A | P10: CTCF
A11: ZBTB7A | B11: 7005 | C11: F | D11: 1 | E11: F | F11: 0.0001 | G11: F | H11: F | I11: F | J11: F | K11: F | L11: F | M11: F | N11: F | O11: A | P11: ZBTB7A
A12: HOXA10 | B12: 6476 | C12: F | D12: 1 | E12: F | F12: 0.01 | G12: F | H12: NA | I12: F | J12: NA | K12: F | L12: NA | M12: F | N12: NA | O12: C | P12: #N/A
A13: ZNF768 | B13: 5837 | C13: F | D13: 1 | E13: F | F13: 1 | O13: C | P13: ZNF768
A14: HOXB6 | B14: 5703 | C14: F | D14: NA | E14: F | F14: NA | H14: NA | I14: F | J14: NA | K14: F | L14: NA | M14: F | N14: NA | O14: D | P14: #N/A
A15: RBPJ | B15: 5138 | C15: F | D15: 1 | E15: F | F15: 0.1 | G15: F | H15: NA | I15: F | J15: NA | K15: F | L15: NA | M15: F | N15: NA | O15: A | P15: #N/A
A16: ZIC2 | B16: 4896 | C16: F | D16: 1 | E16: F | F16: 1 | G16: F | H16: 0.001 | I16: F | J16: 1 | K16: F | L16: 1 | M16: F | N16: 1 | O16: D | P16: Zic2
A17: FOXC1 | B17: 4760 | C17: F | D17: NA | E17: F | F17: NA | G17: F | H17: NA | I17: F | J17: NA | K17: F | L17: NA | M17: F | N17: NA | O17: C | P17: #N/A
A18: TBX3 | B18: 4391 | C18: F | D18: NA | E18: F | F18: NA | G18: F | H18: NA | I18: F | J18: NA | K18: F | L18: NA | M18: F | N18: NA | O18: C | P18: #N/A
A19: HES1 | B19: 4325 | C19: F | D19: NA | E19: F | F19: NA | G19: F | H19: NA | I19: F | J19: NA | K19: F | L19: NA | M19: 6.78e-07 | N19: NA | O19: D | P19: #N/A
A20: MAZ | B20: 3968 | C20: 1.93e-12 | D20: 0.001 | E20: F | F20: 1e-08 | H20: 1e-159 | I20: F | J20: 0 | K20: 0 | L20: 1e-25 | M20: 0 | N20: 1e-22 | O20: A | P20: Maz
A21: SMARCA1 | B21: 3745 | C21: F | D21: NA | E21: F | F21: NA | G21: F | H21: NA | I21: F | J21: NA | K21: F | L21: NA | M21: F | N21: NA | O21: C | P21: #N/A
A22: HOXC9 | B22: 3331 | C22: F | D22: 0.1 | E22: F | F22: 1 | H22: 0.1 | I22: F | J22: 0.1 | K22: F | L22: 1 | M22: F | N22: 0.1 | O22: C | P22: Hoxc9
A23: ZNF282 | B23: 2959 | C23: F | D23: NA | E23: F | F23: NA | G23: F | H23: NA | I23: F | J23: NA | K23: F | L23: NA | M23: F | N23: NA | O23: D | P23: #N/A
A24: FOXJ3 | B24: 2303 | C24: F | D24: NA | E24: F | F24: NA | G24: F | H24: NA | I24: F | J24: NA | K24: F | L24: NA | M24: F | N24: NA | O24: A | P24: #N/A
A25: RELA | B25: 2123 | C25: F | D25: NA | E25: F | F25: NA | G25: F | H25: NA | I25: F | J25: NA | K25: F | L25: NA | M25: F | N25: NA | O25: A | P25: #N/A
A26: HOXB8 | B26: 1980 | C26: F | D26: NA | E26: F | F26: NA | G26: F | H26: NA | I26: F | J26: NA | K26: F | L26: NA | M26: F | N26: NA | O26: C | P26: #N/A
A27: MEF2D | B27: 1764 | C27: F | D27: 1 | E27: F | F27: NA | G27: 0.00432 | H27: 1 | I27: F | J27: 0.01 | K27: F | L27: 1 | M27: F | N27: 1 | O27: A | P27: Mef2d
A28: HOXA5 | B28: 1758 | C28: F | D28: NA | E28: F | F28: NA | G28: F | H28: NA | I28: F | J28: NA | K28: F | L28: NA | M28: F | N28: NA | O28: D | P28: #N/A
A29: ZNF143 | B29: 1736 | C29: F | D29: 1 | E29: F | F29: 1 | G29: F | H29: F | I29: F | J29: F | K29: F | L29: F | M29: F | N29: F | O29: A | P29: ZNF143
A30: ETS2 | B30: 1637 | C30: F | D30: NA | E30: F | F30: NA | G30: F | H30: NA | I30: F | J30: NA | K30: F | L30: NA | M30: F | N30: NA | O30: B | P30: #N/A
A31: NRF1 | B31: 1416 | C31: F | D31: 1e-22 | E31: F | F31: 1e-18 | G31: F | H31: 1e-24 | I31: F | J31: 1e-107 | K31: 7.86e-305 | L31: 1 | M31: 0 | N31: 1e-69 | O31: A | P31: NRF1
A32: MSX2 | B32: 1277 | C32: F | D32: NA | E32: F | F32: NA | G32: F | H32: NA | I32: F | J32: NA | K32: F | L32: NA | M32: F | N32: NA | O32: D | P32: #N/A
A33: HOXD10 | B33: 1224 | C33: F | D33: 1 | E33: F | F33: 1 | G33: F | H33: NA | I33: F | J33: NA | K33: F | L33: NA | M33: F | N33: NA | O33: D | P33: #N/A
A34: SREBF2 | B34: 1211 | C34: F | D34: NA | E34: F | F34: NA | G34: F | H34: NA | I34: F | J34: NA | K34: F | L34: NA | M34: F | N34: NA | O34: B | P34: #N/A
A35: FOXK1 | B35: 1202 | C35: F | D35: 1 | E35: F | F35: 1 | G35: F | H35: 1 | I35: F | J35: 1e-25 | K35: F | L35: 1 | M35: F | N35: 1 | O35: A | P35: FOXK1
A36: EPAS1 | B36: 1046 | C36: F | D36: NA | E36: F | F36: NA | G36: F | H36: NA | I36: F | J36: NA | K36: F | L36: NA | M36: 7.8e-15 | N36: NA | O36: B | P36: #N/A
A37: MEF2A | B37: 1027 | C37: F | D37: 1 | E37: F | F37: 1 | G37: F | H37: NA | I37: F | J37: NA | K37: F | L37: NA | M37: F | N37: NA | O37: A | P37: #N/A
A39: F= Target motif not found in results; NA= TF not present in library
A40: Colored rows are using HOCOMOCO v11 Full dataset (with low quality D)

Sheet known_motifs
A1: TF | B1: Count of Cells | C1: HOMER | D1: AME-MEME (HOCOMOCO v11 core) | E1: AME-MEME (HOCOMOCO v11 full) | F1: Codebook
A2: CTCF | B2: 10410 | C2: CTCF | D2: =_xlfn.XLOOKUP(A2, HOCOMOCOv11_core_annotation_HUM!$B:$B, HOCOMOCOv11_core_annotation_HUM!$D:$D, "Missing") | E2: =_xlfn.XLOOKUP(A2, HOCOMOCOv11_full_annotation_HUM!$B:$B, HOCOMOCOv11_full_annotation_HUM!$D:$D, "Missing") | F2: CTCF
A3: E2F3 | B3: 30622 | C3: E2F3 | D3: =_xlfn.XLOOKUP(A3, HOCOMOCOv11_core_annotation_HUM!$B:$B, HOCOMOCOv11_core_annotation_HUM!$D:$D, "Missing") | E3: =_xlfn.XLOOKUP(A3, HOCOMOCOv11_full_annotation_HUM!$B:$B, HOCOMOCOv11_full_annotation_HUM!$D:$D, "Missing") | F3: Missing
A4: FOXJ3 | B4: 2303 | C4: #N/A | D4: =_xlfn.XLOOKUP(A4, HOCOMOCOv11_core_annotation_HUM!$B:$B, HOCOMOCOv11_core_annotation_HUM!$D:$D, "Missing") | E4: =_xlfn.XLOOKUP(A4, HOCOMOCOv11_full_annotation_HUM!$B:$B, HOCOMOCOv11_full_annotation_HUM!$D:$D, "Missing") | F4: Missing
A5: FOXK1 | B5: 1202 | C5: FOXK1 | D5: =_xlfn.XLOOKUP(A5, HOCOMOCOv11_core_annotation_HUM!$B:$B, HOCOMOCOv11_core_annotation_HUM!$D:$D, "Missing") | E5: =_xlfn.XLOOKUP(A5, HOCOMOCOv11_full_annotation_HUM!$B:$B, HOCOMOCOv11_full_annotation_HUM!$D:$D, "Missing") | F5: Missing
A6: MAZ | B6: 3968 | C6: Maz | D6: =_xlfn.XLOOKUP(A6, HOCOMOCOv11_core_annotation_HUM!$B:$B, HOCOMOCOv11_core_annotation_HUM!$D:$D, "Missing") | E6: =_xlfn.XLOOKUP(A6, HOCOMOCOv11_full_annotation_HUM!$B:$B, HOCOMOCOv11_full_annotation_HUM!$D:$D, "Missing") | F6: Missing
A7: MEF2A | B7: 1027 | C7: #N/A | D7: =_xlfn.XLOOKUP(A7, HOCOMOCOv11_core_annotation_HUM!$B:$B, HOCOMOCOv11_core_annotation_HUM!$D:$D, "Missing") | E7: =_xlfn.XLOOKUP(A7, HOCOMOCOv11_full_annotation_HUM!$B:$B, HOCOMOCOv11_full_annotation_HUM!$D:$D, "Missing") | F7: Missing
A8: MEF2D | B8: 1764 | C8: Mef2d | D8: =_xlfn.XLOOKUP(A8, HOCOMOCOv11_core_annotation_HUM!$B:$B, HOCOMOCOv11_core_annotation_HUM!$D:$D, "Missing") | E8: =_xlfn.XLOOKUP(A8, HOCOMOCOv11_full_annotation_HUM!$B:$B, HOCOMOCOv11_full_annotation_HUM!$D:$D, "Missing") | F8: Missing
A9: NFYA | B9: 70292 | C9: #N/A | D9: =_xlfn.XLOOKUP(A9, HOCOMOCOv11_core_annotation_HUM!$B:$B, HOCOMOCOv11_core_annotation_HUM!$D:$D, "Missing") | E9: =_xlfn.XLOOKUP(A9, HOCOMOCOv11_full_annotation_HUM!$B:$B, HOCOMOCOv11_full_annotation_HUM!$D:$D, "Missing") | F9: Missing
A10: NRF1 | B10: 1416 | C10: NRF1 | D10: =_xlfn.XLOOKUP(A10, HOCOMOCOv11_core_annotation_HUM!$B:$B, HOCOMOCOv11_core_annotation_HUM!$D:$D, "Missing") | E10: =_xlfn.XLOOKUP(A10, HOCOMOCOv11_full_annotation_HUM!$B:$B, HOCOMOCOv11_full_annotation_HUM!$D:$D, "Missing") | F10: Missing
A11: ZBTB7A | B11: 7005 | C11: ZBTB7A | D11: =_xlfn.XLOOKUP(A11, HOCOMOCOv11_core_annotation_HUM!$B:$B, HOCOMOCOv11_core_annotation_HUM!$D:$D, "Missing") | E11: =_xlfn.XLOOKUP(A11, HOCOMOCOv11_full_annotation_HUM!$B:$B, HOCOMOCOv11_full_annotation_HUM!$D:$D, "Missing") | F11: Missing
A12: RBPJ | B12: 5138 | C12: #N/A | D12: =_xlfn.XLOOKUP(A12, HOCOMOCOv11_core_annotation_HUM!$B:$B, HOCOMOCOv11_core_annotation_HUM!$D:$D, "Missing") | E12: =_xlfn.XLOOKUP(A12, HOCOMOCOv11_full_annotation_HUM!$B:$B, HOCOMOCOv11_full_annotation_HUM!$D:$D, "Missing") | F12: Missing
A13: RELA | B13: 2123 | C13: #N/A | D13: =_xlfn.XLOOKUP(A13, HOCOMOCOv11_core_annotation_HUM!$B:$B, HOCOMOCOv11_core_annotation_HUM!$D:$D, "Missing") | E13: =_xlfn.XLOOKUP(A13, HOCOMOCOv11_full_annotation_HUM!$B:$B, HOCOMOCOv11_full_annotation_HUM!$D:$D, "Missing") | F13: Missing
A14: ZNF143 | B14: 1736 | C14: ZNF143 | D14: =_xlfn.XLOOKUP(A14, HOCOMOCOv11_core_annotation_HUM!$B:$B, HOCOMOCOv11_core_annotation_HUM!$D:$D, "Missing") | E14: =_xlfn.XLOOKUP(A14, HOCOMOCOv11_full_annotation_HUM!$B:$B, HOCOMOCOv11_full_annotation_HUM!$D:$D, "Missing") | F14: Missing
A15: EPAS1 | B15: 1046 | C15: #N/A | D15: =_xlfn.XLOOKUP(A15, HOCOMOCOv11_core_annotation_HUM!$B:$B, HOCOMOCOv11_core_annotation_HUM!$D:$D, "Missing") | E15: =_xlfn.XLOOKUP(A15, HOCOMOCOv11_full_annotation_HUM!$B:$B, HOCOMOCOv11_full_annotation_HUM!$D:$D, "Missing") | F15: Missing
A16: ETS2 | B16: 1637 | C16: #N/A | D16: =_xlfn.XLOOKUP(A16, HOCOMOCOv11_core_annotation_HUM!$B:$B, HOCOMOCOv11_core_annotation_HUM!$D:$D, "Missing") | E16: =_xlfn.XLOOKUP(A16, HOCOMOCOv11_full_annotation_HUM!$B:$B, HOCOMOCOv11_full_annotation_HUM!$D:$D, "Missing") | F16: Missing
A17: SOX4 | B17: 64652 | C17: Sox4 | D17: =_xlfn.XLOOKUP(A17, HOCOMOCOv11_core_annotation_HUM!$B:$B, HOCOMOCOv11_core_annotation_HUM!$D:$D, "Missing") | E17: =_xlfn.XLOOKUP(A17, HOCOMOCOv11_full_annotation_HUM!$B:$B, HOCOMOCOv11_full_annotation_HUM!$D:$D, "Missing") | F17: Missing
A18: SREBF2 | B18: 1211 | C18: #N/A | D18: =_xlfn.XLOOKUP(A18, HOCOMOCOv11_core_annotation_HUM!$B:$B, HOCOMOCOv11_core_annotation_HUM!$D:$D, "Missing") | E18: =_xlfn.XLOOKUP(A18, HOCOMOCOv11_full_annotation_HUM!$B:$B, HOCOMOCOv11_full_annotation_HUM!$D:$D, "Missing") | F18: Missing
A19: FOXC1 | B19: 4760 | C19: #N/A | D19: =_xlfn.XLOOKUP(A19, HOCOMOCOv11_core_annotation_HUM!$B:$B, HOCOMOCOv11_core_annotation_HUM!$D:$D, "Missing") | E19: =_xlfn.XLOOKUP(A19, HOCOMOCOv11_full_annotation_HUM!$B:$B, HOCOMOCOv11_full_annotation_HUM!$D:$D, "Missing") | F19: Missing
A20: TBX3 | B20: 4391 | C20: #N/A | D20: =_xlfn.XLOOKUP(A20, HOCOMOCOv11_core_annotation_HUM!$B:$B, HOCOMOCOv11_core_annotation_HUM!$D:$D, "Missing") | E20: =_xlfn.XLOOKUP(A20, HOCOMOCOv11_full_annotation_HUM!$B:$B, HOCOMOCOv11_full_annotation_HUM!$D:$D, "Missing") | F20: Missing
A21: HOXA10 | B21: 6476 | C21: #N/A | D21: =_xlfn.XLOOKUP(A21, HOCOMOCOv11_core_annotation_HUM!$B:$B, HOCOMOCOv11_core_annotation_HUM!$D:$D, "Missing") | E21: =_xlfn.XLOOKUP(A21, HOCOMOCOv11_full_annotation_HUM!$B:$B, HOCOMOCOv11_full_annotation_HUM!$D:$D, "Missing") | F21: Missing
A22: ZNF768 | B22: 5837 | C22: ZNF768 | D22: =_xlfn.XLOOKUP(A22, HOCOMOCOv11_core_annotation_HUM!$B:$B, HOCOMOCOv11_core_annotation_HUM!$D:$D, "Missing") | E22: =_xlfn.XLOOKUP(A22, HOCOMOCOv11_full_annotation_HUM!$B:$B, HOCOMOCOv11_full_annotation_HUM!$D:$D, "Missing") | F22: Missing
A23: SMARCA1 | B23: 3745 | C23: #N/A | D23: =_xlfn.XLOOKUP(A23, HOCOMOCOv11_core_annotation_HUM!$B:$B, HOCOMOCOv11_core_annotation_HUM!$D:$D, "Missing") | E23: =_xlfn.XLOOKUP(A23, HOCOMOCOv11_full_annotation_HUM!$B:$B, HOCOMOCOv11_full_annotation_HUM!$D:$D, "Missing") | F23: Missing
A24: HOXC9 | B24: 3331 | C24: Hoxc9 | D24: =_xlfn.XLOOKUP(A24, HOCOMOCOv11_core_annotation_HUM!$B:$B, HOCOMOCOv11_core_annotation_HUM!$D:$D, "Missing") | E24: =_xlfn.XLOOKUP(A24, HOCOMOCOv11_full_annotation_HUM!$B:$B, HOCOMOCOv11_full_annotation_HUM!$D:$D, "Missing") | F24: Missing
A25: HOXB8 | B25: 1980 | C25: #N/A | D25: =_xlfn.XLOOKUP(A25, HOCOMOCOv11_core_annotation_HUM!$B:$B, HOCOMOCOv11_core_annotation_HUM!$D:$D, "Missing") | E25: =_xlfn.XLOOKUP(A25, HOCOMOCOv11_full_annotation_HUM!$B:$B, HOCOMOCOv11_full_annotation_HUM!$D:$D, "Missing") | F25: Missing
A26: MLX | B26: 23262 | C26: #N/A | D26: =_xlfn.XLOOKUP(A26, HOCOMOCOv11_core_annotation_HUM!$B:$B, HOCOMOCOv11_core_annotation_HUM!$D:$D, "Missing") | E26: =_xlfn.XLOOKUP(A26, HOCOMOCOv11_full_annotation_HUM!$B:$B, HOCOMOCOv11_full_annotation_HUM!$D:$D, "Missing") | F26: Missing
A27: DDIT3 | B27: 22129 | C27: #N/A | D27: =_xlfn.XLOOKUP(A27, HOCOMOCOv11_core_annotation_HUM!$B:$B, HOCOMOCOv11_core_annotation_HUM!$D:$D, "Missing") | E27: =_xlfn.XLOOKUP(A27, HOCOMOCOv11_full_annotation_HUM!$B:$B, HOCOMOCOv11_full_annotation_HUM!$D:$D, "Missing") | F27: Missing
A28: E4F1 | B28: 12061 | C28: #N/A | D28: =_xlfn.XLOOKUP(A28, HOCOMOCOv11_core_annotation_HUM!$B:$B, HOCOMOCOv11_core_annotation_HUM!$D:$D, "Missing") | E28: =_xlfn.XLOOKUP(A28, HOCOMOCOv11_full_annotation_HUM!$B:$B, HOCOMOCOv11_full_annotation_HUM!$D:$D, "Missing") | F28: Missing
A29: HOXB6 | B29: 5703 | C29: #N/A | D29: =_xlfn.XLOOKUP(A29, HOCOMOCOv11_core_annotation_HUM!$B:$B, HOCOMOCOv11_core_annotation_HUM!$D:$D, "Missing") | E29: =_xlfn.XLOOKUP(A29, HOCOMOCOv11_full_annotation_HUM!$B:$B, HOCOMOCOv11_full_annotation_HUM!$D:$D, "Missing") | F29: Missing
A30: ZIC2 | B30: 4896 | C30: Zic2 | D30: =_xlfn.XLOOKUP(A30, HOCOMOCOv11_core_annotation_HUM!$B:$B, HOCOMOCOv11_core_annotation_HUM!$D:$D, "Missing") | E30: =_xlfn.XLOOKUP(A30, HOCOMOCOv11_full_annotation_HUM!$B:$B, HOCOMOCOv11_full_annotation_HUM!$D:$D, "Missing") | F30: Missing
A31: HES1 | B31: 4325 | C31: #N/A | D31: =_xlfn.XLOOKUP(A31, HOCOMOCOv11_core_annotation_HUM!$B:$B, HOCOMOCOv11_core_annotation_HUM!$D:$D, "Missing") | E31: =_xlfn.XLOOKUP(A31, HOCOMOCOv11_full_annotation_HUM!$B:$B, HOCOMOCOv11_full_annotation_HUM!$D:$D, "Missing") | F31: Missing
A32: ZNF282 | B32: 2959 | C32: #N/A | D32: =_xlfn.XLOOKUP(A32, HOCOMOCOv11_core_annotation_HUM!$B:$B, HOCOMOCOv11_core_annotation_HUM!$D:$D, "Missing") | E32: =_xlfn.XLOOKUP(A32, HOCOMOCOv11_full_annotation_HUM!$B:$B, HOCOMOCOv11_full_annotation_HUM!$D:$D, "Missing") | F32: Missing
A33: HOXA5 | B33: 1758 | C33: #N/A | D33: =_xlfn.XLOOKUP(A33, HOCOMOCOv11_core_annotation_HUM!$B:$B, HOCOMOCOv11_core_annotation_HUM!$D:$D, "Missing") | E33: =_xlfn.XLOOKUP(A33, HOCOMOCOv11_full_annotation_HUM!$B:$B, HOCOMOCOv11_full_annotation_HUM!$D:$D, "Missing") | F33: Missing
A34: MSX2 | B34: 1277 | C34: #N/A | D34: =_xlfn.XLOOKUP(A34, HOCOMOCOv11_core_annotation_HUM!$B:$B, HOCOMOCOv11_core_annotation_HUM!$D:$D, "Missing") | E34: =_xlfn.XLOOKUP(A34, HOCOMOCOv11_full_annotation_HUM!$B:$B, HOCOMOCOv11_full_annotation_HUM!$D:$D, "Missing") | F34: Missing
A35: HOXD10 | B35: 1224 | C35: #N/A | D35: =_xlfn.XLOOKUP(A35, HOCOMOCOv11_core_annotation_HUM!$B:$B, HOCOMOCOv11_core_annotation_HUM!$D:$D, "Missing") | E35: =_xlfn.XLOOKUP(A35, HOCOMOCOv11_full_annotation_HUM!$B:$B, HOCOMOCOv11_full_annotation_HUM!$D:$D, "Missing") | F35: Missing
A36: RBBP4 | B36: 181396 | C36: #N/A | D36: =_xlfn.XLOOKUP(A36, HOCOMOCOv11_core_annotation_HUM!$B:$B, HOCOMOCOv11_core_annotation_HUM!$D:$D, "Missing") | E36: =_xlfn.XLOOKUP(A36, HOCOMOCOv11_full_annotation_HUM!$B:$B, HOCOMOCOv11_full_annotation_HUM!$D:$D, "Missing") | F36: Missing
A37: XPA | B37: 50752 | C37: #N/A | D37: =_xlfn.XLOOKUP(A37, HOCOMOCOv11_core_annotation_HUM!$B:$B, HOCOMOCOv11_core_annotation_HUM!$D:$D, "Missing") | E37: =_xlfn.XLOOKUP(A37, HOCOMOCOv11_full_annotation_HUM!$B:$B, HOCOMOCOv11_full_annotation_HUM!$D:$D, "Missing") | F37: Missing
A38: RBBP7 | B38: 39619 | C38: #N/A | D38: =_xlfn.XLOOKUP(A38, HOCOMOCOv11_core_annotation_HUM!$B:$B, HOCOMOCOv11_core_annotation_HUM!$D:$D, "Missing") | E38: =_xlfn.XLOOKUP(A38, HOCOMOCOv11_full_annotation_HUM!$B:$B, HOCOMOCOv11_full_annotation_HUM!$D:$D, "Missing") | F38: Missing
A39: ZNF507 | B39: 30870 | C39: #N/A | D39: =_xlfn.XLOOKUP(A39, HOCOMOCOv11_core_annotation_HUM!$B:$B, HOCOMOCOv11_core_annotation_HUM!$D:$D, "Missing") | E39: =_xlfn.XLOOKUP(A39, HOCOMOCOv11_full_annotation_HUM!$B:$B, HOCOMOCOv11_full_annotation_HUM!$D:$D, "Missing") | F39: ZNF507
A40: NME2 | B40: 30095 | C40: #N/A | D40: =_xlfn.XLOOKUP(A40, HOCOMOCOv11_core_annotation_HUM!$B:$B, HOCOMOCOv11_core_annotation_HUM!$D:$D, "Missing") | E40: =_xlfn.XLOOKUP(A40, HOCOMOCOv11_full_annotation_HUM!$B:$B, HOCOMOCOv11_full_annotation_HUM!$D:$D, "Missing") | F40: Missing
...

Sheet HOCOMOCOv11_full_annotation_HUM
A1: Model | B1: Transcription factor | C1: Model length | D1: Quality | E1: Model rank | F1: Consensus | G1: Model release | H1: Data source | I1: Best auROC (human) | J1: Best auROC (mouse) | K1: Peak sets in benchmark (human) | L1: Peak sets in benchmark (mouse) | M1: Aligned words | N1: TF family | O1: TF subfamily | P1: HGNC | Q1: EntrezGene | R1: UniProt ID | S1: UniProt AC
A2: AHR_HUMAN.H11MO.0.B | B2: AHR | C2: 9 | D2: B | E2: 0 | F2: dKhGCGTGh | G2: HOCOMOCOv9 | H2: Integrative | M2: 157 | N2: PAS domain factors{1.2.5} | O2: Ahr-like factors{1.2.5.1} | P2: 348 | Q2: 196 | R2: AHR_HUMAN | S2: P35869
A3: AIRE_HUMAN.H11MO.0.C | B3: AIRE | C3: 18 | D3: C | E3: 0 | F3: hnnGGWWnddWWGGdbWh | G3: HOCOMOCOv9 | H3: Integrative | M3: 41 | N3: AIRE{5.3.1} | O3: AIRE{5.3.1.0.1} | P3: 360 | Q3: 326 | R3: AIRE_HUMAN | S3: O43918
A4: ALX1_HUMAN.H11MO.0.B | B4: ALX1 | C4: 12 | D4: B | E4: 0 | F4: vTRATYGnATTA | G4: HOCOMOCOv9 | H4: Integrative | M4: 33 | N4: Paired-related HD factors{3.1.3} | O4: ALX{3.1.3.1} | P4: 1494 | Q4: 8092 | R4: ALX1_HUMAN | S4: Q15699
A5: ALX3_HUMAN.H11MO.0.D | B5: ALX3 | C5: 11 | D5: D | E5: 0 | F5: TAATTARMTWW | G5: HOCOMOCOv10 | H5: HT-SELEX | M5: 8583 | N5: Paired-related HD factors{3.1.3} | O5: ALX{3.1.3.1} | P5: 449 | Q5: 257 | R5: ALX3_HUMAN | S5: O95076
A6: ALX4_HUMAN.H11MO.0.D | B6: ALX4 | C6: 12 | D6: D | E6: 0 | F6: hTAATTARATTA | G6: HOCOMOCOv10 | H6: HT-SELEX | M6: 23663 | N6: Paired-related HD factors{3.1.3} | O6: ALX{3.1.3.1} | P6: 450 | Q6: 60529 | R6: ALX4_HUMAN | S6: Q9H161
A7: ANDR_HUMAN.H11MO.0.A | B7: AR | C7: 18 | D7: A | E7: 0 | F7: WKThYYddbhTRTTTRYh | G7: HOCOMOCOv11 | H7: ChIP-Seq | I7: 0.9598371 | J7: 0.81079115 | K7: 461 | L7: 57 | M7: 499 | N7: Steroid hormone receptors (NR3){2.1.1} | O7: GR-like receptors (NR3C){2.1.1.1} | P7: 644 | Q7: 367 | R7: ANDR_HUMAN | S7: P10275
A8: ANDR_HUMAN.H11MO.1.A | B8: AR | C8: 16 | D8: A | E8: 1 | F8: dGnACWbTbWGTdCYb | G8: HOCOMOCOv11 | H8: ChIP-Seq | I8: 0.96980048 | J8: 0.99120183 | K8: 461 | L8: 57 | M8: 500 | N8: Steroid hormone receptors (NR3){2.1.1} | O8: GR-like receptors (NR3C){2.1.1.1} | P8: 644 | Q8: 367 | R8: ANDR_HUMAN | S8: P10275
A9: ANDR_HUMAN.H11MO.2.A | B9: AR | C9: 12 | D9: A | E9: 2 | F9: nhbTGTKCYhdb | G9: HOCOMOCOv11 | H9: ChIP-Seq | I9: 0.90120128 | J9: 0.88735693 | K9: 461 | L9: 57 | M9: 500 | N9: Steroid hormone receptors (NR3){2.1.1} | O9: GR-like receptors (NR3C){2.1.1.1} | P9: 644 | Q9: 367 | R9: ANDR_HUMAN | S9: P10275
A10: AP2A_HUMAN.H11MO.0.A | B10: TFAP2A | C10: 15 | D10: A | E10: 0 | F10: dddSCCTGRGGShdd | G10: HOCOMOCOv10 | H10: ChIP-Seq | I10: 0.95556087 | J10: 0.93658649 | K10: 13 | L10: 13 | M10: 500 | N10: AP-2{1.3.1} | O10: AP-2alpha{1.3.1.0.1} | P10: 11742 | Q10: 7020 | R10: AP2A_HUMAN | S10: P05549
A11: AP2B_HUMAN.H11MO.0.B | B11: TFAP2B | C11: 10 | D11: B | E11: 0 | F11: GSCYGRGGRv | G11: HOCOMOCOv9 | H11: Integrative | M11: 30 | N11: AP-2{1.3.1} | O11: AP-2beta{1.3.1.0.2} | P11: 11743 | Q11: 7021 | R11: AP2B_HUMAN | S11: Q92481
A12: AP2C_HUMAN.H11MO.0.A | B12: TFAP2C | C12: 14 | D12: A | E12: 0 | F12: vddSCCTGRGGShv | G12: HOCOMOCOv10 | H12: ChIP-Seq | I12: 0.94994854 | J12: 0.94118439 | K12: 18 | L12: 6 | M12: 501 | N12: AP-2{1.3.1} | O12: AP-2gamma{1.3.1.0.3} | P12: 11744 | Q12: 7022 | R12: AP2C_HUMAN | S12: Q92754
A13: AP2D_HUMAN.H11MO.0.D | B13: TFAP2D | C13: 14 | D13: D | E13: 0 | F13: nGbCCGRGGCnCGY | G13: HOCOMOCOv9 | H13: Integrative | M13: 5 | N13: AP-2{1.3.1} | O13: AP-2delta{1.3.1.0.4} | P13: 15581 | Q13: 83741 | R13: AP2D_HUMAN | S13: Q7Z6R9
A14: ARI3A_HUMAN.H11MO.0.D | B14: ARID3A | C14: 22 | D14: D | E14: 0 | F14: dWTTAAWYvRdWWYAAAWYWWW | G14: HOCOMOCOv9 | H14: Integrative | M14: 44 | N14: ARID-related factors{3.7.1} | O14: ARID3{3.7.1.3} | P14: 3031 | Q14: 1820 | R14: ARI3A_HUMAN | S14: Q99856
A15: ARI5B_HUMAN.H11MO.0.C | B15: ARID5B | C15: 13 | D15: C | E15: 0 | F15: nbYKnRTATTSKd | G15: HOCOMOCOv9 | H15: Integrative | M15: 19 | N15: ARID-related factors{3.7.1} | O15: ARID5{3.7.1.5} | P15: 17362 | Q15: 84159 | R15: ARI5B_HUMAN | S15: Q14865
A16: ARNT2_HUMAN.H11MO.0.D | B16: ARNT2 | C16: 12 | D16: D | E16: 0 | F16: RnSGTGGvRSRS | G16: HOCOMOCOv9 | H16: Integrative | M16: 18 | N16: PAS domain factors{1.2.5} | O16: Arnt-like factors{1.2.5.2} | P16: 16876 | Q16: 9915 | R16: ARNT2_HUMAN | S16: Q9HBZ2
A17: ARNT_HUMAN.H11MO.0.B | B17: ARNT | C17: 9 | D17: B | E17: 0 | F17: vdRCGTGMh | G17: HOCOMOCOv11 | H17: ChIP-Seq | I17: 0.93577686 | K17: 8 | M17: 500 | N17: PAS domain factors{1.2.5} | O17: Arnt-like factors{1.2.5.2} | P17: 700 | Q17: 405 | R17: ARNT_HUMAN | S17: P27540
A18: ARX_HUMAN.H11MO.0.D | B18: ARX | C18: 13 | D18: D | E18: 0 | F18: hTAATYTAATTWv | G18: HOCOMOCOv10 | H18: HT-SELEX | M18: 623 | N18: Paired-related HD factors{3.1.3} | O18: ARX{3.1.3.3} | P18: 18060 | Q18: 170302 | R18: ARX_HUMAN | S18: Q96QS3
A19: ASCL1_HUMAN.H11MO.0.A | B19: ASCL1 | C19: 14 | D19: A | E19: 0 | F19: hnvCASCTGYYbhh | G19: HOCOMOCOv11 | H19: ChIP-Seq | I19: 0.98549867 | J19: 0.98049328 | K19: 30 | L19: 25 | M19: 480 | N19: MyoD / ASC-related factors{1.2.2} | O19: Achaete-Scute-like factors{1.2.2.2} | P19: 738 | Q19: 429 | R19: ASCL1_HUMAN | S19: P50553
A20: ASCL2_HUMAN.H11MO.0.D | B20: ASCL2 | C20: 9 | D20: D | E20: 0 | F20: vCASCTGCY | G20: HOCOMOCOv11 | H20: ChIP-Seq | I20: 0.59387727 | J20: 0.91956126 | K20: 8 | L20: 9 | M20: 505 | N20: MyoD / ASC-related factors{1.2.2} | O20: Achaete-Scute-like factors{1.2.2.2} | P20: 739 | Q20: 430 | R20: ASCL2_HUMAN | S20: Q99929
A21: ATF1_HUMAN.H11MO.0.B | B21: ATF1 | C21: 11 | D21: B | E21: 0 | F21: ndRTGACGYvd | G21: HOCOMOCOv11 | H21: ChIP-Seq | I21: 0.89168408 | K21: 6 | M21: 500 | N21: CREB-related factors{1.1.7} | O21: CREB-like factors{1.1.7.1} | P21: 783 | Q21: 466 | R21: ATF1_HUMAN | S21: P18846
A22: ATF2_HUMAN.H11MO.0.B | B22: ATF2 | C22: 11 | D22: B | E22: 0 | F22: dvTGAbGWMAb | G22: HOCOMOCOv11 | H22: ChIP-Seq | I22: 0.75088532 | J22: 0.84933689 | K22: 8 | L22: 4 | M22: 502 | N22: Jun-related factors{1.1.1} | O22: ATF-2-like factors{1.1.1.3} | P22: 784 | Q22: 1386 | R22: ATF2_HUMAN | S22: P15336
A23: ATF2_HUMAN.H11MO.1.B | B23: ATF2 | C23: 20 | D23: B | E23: 1 | F23: ddddRATGATGTCAThdhdd | G23: HOCOMOCOv11 | H23: ChIP-Seq | I23: 0.70505998 | J23: 0.80641934 | K23: 8 | L23: 4 | M23: 1294 | N23: Jun-related factors{1.1.1} | O23: ATF-2-like factors{1.1.1.3} | P23: 784 | Q23: 1386 | R23: ATF2_HUMAN | S23: P15336
A24: ATF2_HUMAN.H11MO.2.C | B24: ATF2 | C24: 11 | D24: C | E24: 2 | F24: RRTGACGTCAb | G24: HOCOMOCOv11 | H24: ChIP-Seq | I24: 0.70801467 | J24: 0.79956232 | K24: 8 | L24: 4 | M24: 385 | N24: Jun-related factors{1.1.1} | O24: ATF-2-like factors{1.1.1.3} | P24: 784 | Q24: 1386 | R24: ATF2_HUMAN | S24: P15336
A25: ATF3_HUMAN.H11MO.0.A | B25: ATF3 | C25: 11 | D25: A | E25: 0 | F25: dRTSACGTRRb | G25: HOCOMOCOv11 | H25: ChIP-Seq | I25: 0.92781848 | J25: 0.76418012 | K25: 36 | L25: 16 | M25: 505 | N25: Fos-related factors{1.1.2} | O25: ATF-3-like factors{1.1.2.2} | P25: 785 | Q25: 467 | R25: ATF3_HUMAN | S25: P18847
A26: ATF4_HUMAN.H11MO.0.A | B26: ATF4 | C26: 12 | D26: A | E26: 0 | F26: dnMTGATGCAAY | G26: HOCOMOCOv11 | H26: ChIP-Seq | I26: 0.99788201 | J26: 0.95111049 | K26: 18 | L26: 9 | M26: 500 | N26: ATF-4-related factors{1.1.6} | O26: ATF-4{1.1.6.0.1} | P26: 786 | Q26: 468 | R26: ATF4_HUMAN | S26: P18848
A27: ATF6A_HUMAN.H11MO.0.B | B27: ATF6 | C27: 12 | D27: B | E27: 0 | F27: vKSSTGACGTGG | G27: HOCOMOCOv9 | H27: Integrative | M27: 20 | N27: CREB-related factors{1.1.7} | O27: ATF-6 factors{1.1.7.3} | P27: 791 | Q27: 22926 | R27: ATF6A_HUMAN | S27: P18850
A28: ATF7_HUMAN.H11MO.0.D | B28: ATF7 | C28: 11 | D28: D | E28: 0 | F28: dRTGACGTCAT | G28: HOCOMOCOv10 | H28: HT-SELEX | M28: 13767 | N28: Jun-related factors{1.1.1} | O28: ATF-2-like factors{1.1.1.3} | P28: 792 | Q28: 11016 | R28: ATF7_HUMAN | S28: P17544
A29: ATOH1_HUMAN.H11MO.0.B | B29: ATOH1 | C29: 9 | D29: B | E29: 0 | F29: RRCAGMTGK | G29: HOCOMOCOv11 | H29: ChIP-Seq | I29: 0.75902405 | J29: 0.98836918 | K29: 3 | L29: 4 | M29: 502 | N29: Tal-related factors{1.2.3} | O29: Neurogenin / Atonal-like factors{1.2.3.4} | P29: 797 | Q29: 474 | R29: ATOH1_HUMAN | S29: Q92858
A30: BACH1_HUMAN.H11MO.0.A | B30: BACH1 | C30: 13 | D30: A | E30: 0 | F30: YGCTGAGTCMbbb | G30: HOCOMOCOv10 | H30: ChIP-Seq | M30: 502 | N30: Jun-related factors{1.1.1} | O30: NF-E2-like factors{1.1.1.2} | P30: 935 | Q30: 571 | R30: BACH1_HUMAN | S30: O14867
A31: BACH2_HUMAN.H11MO.0.A | B31: BACH2 | C31: 11 | D31: A | E31: 0 | F31: WGCTKWSTCAb | G31: HOCOMOCOv11 | H31: ChIP-Seq | I31: 0.92580702 | J31: 0.98024126 | K31: 10 | L31: 3 | M31: 500 | N31: Jun-related factors{1.1.1} | O31: NF-E2-like factors{1.1.1.2} | P31: 14078 | Q31: 60468 | R31: BACH2_HUMAN | S31: Q9BYV9
A32: BARH1_HUMAN.H11MO.0.D | B32: BARHL1 | C32: 13 | D32: D | E32: 0 | F32: TAAWYGbYnhTWA | G32: HOCOMOCOv10 | H32: HT-SELEX | M32: 5695 | N32: NK-related factors{3.1.2} | O32: BARHL{3.1.2.1} | P32: 953 | Q32: 56751 | R32: BARH1_HUMAN | S32: Q9BZE3
A33: BARH2_HUMAN.H11MO.0.D | B33: BARHL2 | C33: 18 | D33: D | E33: 0 | F33: vhTAAWYGnYbhhWWWhd | G33: HOCOMOCOv10 | H33: HT-SELEX | M33: 41168 | N33: NK-related factors{3.1.2} | O33: BARHL{3.1.2.1} | P33: 954 | Q33: 343472 | R33: BARH2_HUMAN | S33: Q9NY43
A34: BARX1_HUMAN.H11MO.0.D | B34: BARX1 | C34: 12 | D34: D | E34: 0 | F34: nWMAKKSYTThh | G34: HOCOMOCOv11 | H34: ChIP-Seq | I34: 0.60816347 | J34: 0.831429 | K34: 2 | L34: 2 | M34: 461 | N34: NK-related factors{3.1.2} | O34: BARX{3.1.2.2} | P34: 955 | Q34: 56033 | R34: BARX1_HUMAN | S34: Q9HBU1
A35: BARX2_HUMAN.H11MO.0.D | B35: BARX2 | C35: 10 | D35: D | E35: 0 | F35: hYnWTAATKR | G35: HOCOMOCOv9 | H35: Integrative | M35: 14 | N35: NK-related factors{3.1.2} | O35: BARX{3.1.2.2} | P35: 956 | Q35: 8538 | R35: BARX2_HUMAN | S35: Q9UMQ3
A36: BATF3_HUMAN.H11MO.0.B | B36: BATF3 | C36: 17 | D36: B | E36: 0 | F36: ndSTTYChnWhTGAbdn | G36: HOCOMOCOv11 | H36: ChIP-Seq | J36: 0.96333554 | L36: 5 | M36: 500 | N36: B-ATF-related factors{1.1.4} | O36: B-ATF-3{1.1.4.0.3} | P36: 28915 | Q36: 55509 | R36: BATF3_HUMAN | S36: Q9NR55
A37: BATF_HUMAN.H11MO.0.A | B37: BATF | C37: 18 | D37: A | E37: 0 | F37: dbTYYYddWWTGASTnWb | G37: HOCOMOCOv11 | H37: ChIP-Seq | I37: 0.96321879 | J37: 0.93788743 | K37: 10 | L37: 20 | M37: 500 | N37: B-ATF-related factors{1.1.4} | O37: B-ATF{1.1.4.0.1} | P37: 958 | Q37: 10538 | R37: BATF_HUMAN | S37: Q16520
A38: BATF_HUMAN.H11MO.1.A | B38: BATF | C38: 11 | D38: A | E38: 1 | F38: dMTGAYKCAWh | G38: HOCOMOCOv11 | H38: ChIP-Seq | I38: 0.89031363 | J38: 0.85612825 | K38: 10 | L38: 20 | M38: 500 | N38: B-ATF-related factors{1.1.4} | O38: B-ATF{1.1.4.0.1} | P38: 958 | Q38: 10538 | R38: BATF_HUMAN | S38: Q16520
A39: BC11A_HUMAN.H11MO.0.A | B39: BCL11A | C39: 17 | D39: A | E39: 0 | F39: vdvRvRGGAAvYRRvRv | G39: HOCOMOCOv10 | H39: ChIP-Seq | I39: 0.89958468 | K39: 10 | M39: 500 | N39: Factors with multiple dispersed zinc fingers{2.3.4} | O39: BCL11{2.3.4.15} | P39: 13221 | Q39: 53335 | R39: BC11A_HUMAN | S39: Q9H165
A40: BCL6B_HUMAN.H11MO.0.D | B40: BCL6B | C40: 11 | D40: D | E40: 0 | F40: nYGCTTTCTAG | G40: HOCOMOCOv10 | H40: HT-SELEX | M40: 66 | N40: More than 3 adjacent zinc finger factors{2.3.3} | O40: BCL6 factors{2.3.3.22} | P40: 1002 | Q40: 255877 | R40: BCL6B_HUMAN | S40: Q8N143
...

Sheet HOCOMOCOv11_core_annotation_HUM
A1: Model | B1: Transcription factor | C1: Model length | D1: Quality | E1: Model rank | F1: Consensus | G1: Model release | H1: Data source | I1: Best auROC (human) | J1: Best auROC (mouse) | K1: Peak sets in benchmark (human) | L1: Peak sets in benchmark (mouse) | M1: Aligned words | N1: TF family | O1: TF subfamily | P1: HGNC | Q1: EntrezGene | R1: UniProt ID | S1: UniProt AC
A2: AHR_HUMAN.H11MO.0.B | B2: AHR | C2: 9 | D2: B | E2: 0 | F2: dKhGCGTGh | G2: HOCOMOCOv9 | H2: Integrative | M2: 157 | N2: PAS domain factors{1.2.5} | O2: Ahr-like factors{1.2.5.1} | P2: 348 | Q2: 196 | R2: AHR_HUMAN | S2: P35869
A3: AIRE_HUMAN.H11MO.0.C | B3: AIRE | C3: 18 | D3: C | E3: 0 | F3: hnnGGWWnddWWGGdbWh | G3: HOCOMOCOv9 | H3: Integrative | M3: 41 | N3: AIRE{5.3.1} | O3: AIRE{5.3.1.0.1} | P3: 360 | Q3: 326 | R3: AIRE_HUMAN | S3: O43918
A4: ALX1_HUMAN.H11MO.0.B | B4: ALX1 | C4: 12 | D4: B | E4: 0 | F4: vTRATYGnATTA | G4: HOCOMOCOv9 | H4: Integrative | M4: 33 | N4: Paired-related HD factors{3.1.3} | O4: ALX{3.1.3.1} | P4: 1494 | Q4: 8092 | R4: ALX1_HUMAN | S4: Q15699
A5: ANDR_HUMAN.H11MO.0.A | B5: AR | C5: 18 | D5: A | E5: 0 | F5: WKThYYddbhTRTTTRYh | G5: HOCOMOCOv11 | H5: ChIP-Seq | I5: 0.9598371 | J5: 0.81079115 | K5: 461 | L5: 57 | M5: 499 | N5: Steroid hormone receptors (NR3){2.1.1} | O5: GR-like receptors (NR3C){2.1.1.1} | P5: 644 | Q5: 367 | R5: ANDR_HUMAN | S5: P10275
A6: AP2A_HUMAN.H11MO.0.A | B6: TFAP2A | C6: 15 | D6: A | E6: 0 | F6: dddSCCTGRGGShdd | G6: HOCOMOCOv10 | H6: ChIP-Seq | I6: 0.95556087 | J6: 0.93658649 | K6: 13 | L6: 13 | M6: 500 | N6: AP-2{1.3.1} | O6: AP-2alpha{1.3.1.0.1} | P6: 11742 | Q6: 7020 | R6: AP2A_HUMAN | S6: P05549
A7: AP2B_HUMAN.H11MO.0.B | B7: TFAP2B | C7: 10 | D7: B | E7: 0 | F7: GSCYGRGGRv | G7: HOCOMOCOv9 | H7: Integrative | M7: 30 | N7: AP-2{1.3.1} | O7: AP-2beta{1.3.1.0.2} | P7: 11743 | Q7: 7021 | R7: AP2B_HUMAN | S7: Q92481
A8: AP2C_HUMAN.H11MO.0.A | B8: TFAP2C | C8: 14 | D8: A | E8: 0 | F8: vddSCCTGRGGShv | G8: HOCOMOCOv10 | H8: ChIP-Seq | I8: 0.94994854 | J8: 0.94118439 | K8: 18 | L8: 6 | M8: 501 | N8: AP-2{1.3.1} | O8: AP-2gamma{1.3.1.0.3} | P8: 11744 | Q8: 7022 | R8: AP2C_HUMAN | S8: Q92754
A9: ARI5B_HUMAN.H11MO.0.C | B9: ARID5B | C9: 13 | D9: C | E9: 0 | F9: nbYKnRTATTSKd | G9: HOCOMOCOv9 | H9: Integrative | M9: 19 | N9: ARID-related factors{3.7.1} | O9: ARID5{3.7.1.5} | P9: 17362 | Q9: 84159 | R9: ARI5B_HUMAN | S9: Q14865
A10: ARNT_HUMAN.H11MO.0.B | B10: ARNT | C10: 9 | D10: B | E10: 0 | F10: vdRCGTGMh | G10: HOCOMOCOv11 | H10: ChIP-Seq | I10: 0.93577686 | K10: 8 | M10: 500 | N10: PAS domain factors{1.2.5} | O10: Arnt-like factors{1.2.5.2} | P10: 700 | Q10: 405 | R10: ARNT_HUMAN | S10: P27540
A11: ASCL1_HUMAN.H11MO.0.A | B11: ASCL1 | C11: 14 | D11: A | E11: 0 | F11: hnvCASCTGYYbhh | G11: HOCOMOCOv11 | H11: ChIP-Seq | I11: 0.98549867 | J11: 0.98049328 | K11: 30 | L11: 25 | M11: 480 | N11: MyoD / ASC-related factors{1.2.2} | O11: Achaete-Scute-like factors{1.2.2.2} | P11: 738 | Q11: 429 | R11: ASCL1_HUMAN | S11: P50553
A12: ATF1_HUMAN.H11MO.0.B | B12: ATF1 | C12: 11 | D12: B | E12: 0 | F12: ndRTGACGYvd | G12: HOCOMOCOv11 | H12: ChIP-Seq | I12: 0.89168408 | K12: 6 | M12: 500 | N12: CREB-related factors{1.1.7} | O12: CREB-like factors{1.1.7.1} | P12: 783 | Q12: 466 | R12: ATF1_HUMAN | S12: P18846
A13: ATF2_HUMAN.H11MO.0.B | B13: ATF2 | C13: 11 | D13: B | E13: 0 | F13: dvTGAbGWMAb | G13: HOCOMOCOv11 | H13: ChIP-Seq | I13: 0.75088532 | J13: 0.84933689 | K13: 8 | L13: 4 | M13: 502 | N13: Jun-related factors{1.1.1} | O13: ATF-2-like factors{1.1.1.3} | P13: 784 | Q13: 1386 | R13: ATF2_HUMAN | S13: P15336
A14: ATF3_HUMAN.H11MO.0.A | B14: ATF3 | C14: 11 | D14: A | E14: 0 | F14: dRTSACGTRRb | G14: HOCOMOCOv11 | H14: ChIP-Seq | I14: 0.92781848 | J14: 0.76418012 | K14: 36 | L14: 16 | M14: 505 | N14: Fos-related factors{1.1.2} | O14: ATF-3-like factors{1.1.2.2} | P14: 785 | Q14: 467 | R14: ATF3_HUMAN | S14: P18847
A15: ATF4_HUMAN.H11MO.0.A | B15: ATF4 | C15: 12 | D15: A | E15: 0 | F15: dnMTGATGCAAY | G15: HOCOMOCOv11 | H15: ChIP-Seq | I15: 0.99788201 | J15: 0.95111049 | K15: 18 | L15: 9 | M15: 500 | N15: ATF-4-related factors{1.1.6} | O15: ATF-4{1.1.6.0.1} | P15: 786 | Q15: 468 | R15: ATF4_HUMAN | S15: P18848
A16: ATF6A_HUMAN.H11MO.0.B | B16: ATF6 | C16: 12 | D16: B | E16: 0 | F16: vKSSTGACGTGG | G16: HOCOMOCOv9 | H16: Integrative | M16: 20 | N16: CREB-related factors{1.1.7} | O16: ATF-6 factors{1.1.7.3} | P16: 791 | Q16: 22926 | R16: ATF6A_HUMAN | S16: P18850
A17: ATOH1_HUMAN.H11MO.0.B | B17: ATOH1 | C17: 9 | D17: B | E17: 0 | F17: RRCAGMTGK | G17: HOCOMOCOv11 | H17: ChIP-Seq | I17: 0.75902405 | J17: 0.98836918 | K17: 3 | L17: 4 | M17: 502 | N17: Tal-related factors{1.2.3} | O17: Neurogenin / Atonal-like factors{1.2.3.4} | P17: 797 | Q17: 474 | R17: ATOH1_HUMAN | S17: Q92858
A18: BACH1_HUMAN.H11MO.0.A | B18: BACH1 | C18: 13 | D18: A | E18: 0 | F18: YGCTGAGTCMbbb | G18: HOCOMOCOv10 | H18: ChIP-Seq | M18: 502 | N18: Jun-related factors{1.1.1} | O18: NF-E2-like factors{1.1.1.2} | P18: 935 | Q18: 571 | R18: BACH1_HUMAN | S18: O14867
A19: BACH2_HUMAN.H11MO.0.A | B19: BACH2 | C19: 11 | D19: A | E19: 0 | F19: WGCTKWSTCAb | G19: HOCOMOCOv11 | H19: ChIP-Seq | I19: 0.92580702 | J19: 0.98024126 | K19: 10 | L19: 3 | M19: 500 | N19: Jun-related factors{1.1.1} | O19: NF-E2-like factors{1.1.1.2} | P19: 14078 | Q19: 60468 | R19: BACH2_HUMAN | S19: Q9BYV9
A20: BATF3_HUMAN.H11MO.0.B | B20: BATF3 | C20: 17 | D20: B | E20: 0 | F20: ndSTTYChnWhTGAbdn | G20: HOCOMOCOv11 | H20: ChIP-Seq | J20: 0.96333554 | L20: 5 | M20: 500 | N20: B-ATF-related factors{1.1.4} | O20: B-ATF-3{1.1.4.0.3} | P20: 28915 | Q20: 55509 | R20: BATF3_HUMAN | S20: Q9NR55
A21: BATF_HUMAN.H11MO.0.A | B21: BATF | C21: 18 | D21: A | E21: 0 | F21: dbTYYYddWWTGASTnWb | G21: HOCOMOCOv11 | H21: ChIP-Seq | I21: 0.96321879 | J21: 0.93788743 | K21: 10 | L21: 20 | M21: 500 | N21: B-ATF-related factors{1.1.4} | O21: B-ATF{1.1.4.0.1} | P21: 958 | Q21: 10538 | R21: BATF_HUMAN | S21: Q16520
A22: BC11A_HUMAN.H11MO.0.A | B22: BCL11A | C22: 17 | D22: A | E22: 0 | F22: vdvRvRGGAAvYRRvRv | G22: HOCOMOCOv10 | H22: ChIP-Seq | I22: 0.89958468 | K22: 10 | M22: 500 | N22: Factors with multiple dispersed zinc fingers{2.3.4} | O22: BCL11{2.3.4.15} | P22: 13221 | Q22: 53335 | R22: BC11A_HUMAN | S22: Q9H165
A23: BCL6_HUMAN.H11MO.0.A | B23: BCL6 | C23: 13 | D23: A | E23: 0 | F23: bdMYYTCYAGGAA | G23: HOCOMOCOv11 | H23: ChIP-Seq | I23: 0.80230347 | J23: 0.87359178 | K23: 27 | L23: 11 | M23: 500 | N23: More than 3 adjacent zinc finger factors{2.3.3} | O23: BCL6 factors{2.3.3.22} | P23: 1001 | Q23: 604 | R23: BCL6_HUMAN | S23: P41182
A24: BHA15_HUMAN.H11MO.0.B | B24: BHLHA15 | C24: 11 | D24: B | E24: 0 | F24: vvRRCAGCTGK | G24: HOCOMOCOv11 | H24: ChIP-Seq | J24: 0.98809676 | L24: 6 | M24: 500 | N24: Tal-related factors{1.2.3} | O24: Neurogenin / Atonal-like factors{1.2.3.4} | P24: 22265 | Q24: 168620 | R24: BHA15_HUMAN | S24: Q7RTS1
A25: BHE40_HUMAN.H11MO.0.A | B25: BHLHE40 | C25: 10 | D25: A | E25: 0 | F25: dKCACGTGMv | G25: HOCOMOCOv11 | H25: ChIP-Seq | I25: 0.85472299 | J25: 0.95342176 | K25: 10 | L25: 5 | M25: 508 | N25: Hairy-related factors{1.2.4} | O25: Hairy-like factors{1.2.4.1} | P25: 1046 | Q25: 8553 | R25: BHE40_HUMAN | S25: O14503
A26: BMAL1_HUMAN.H11MO.0.A | B26: ARNTL | C26: 11 | D26: A | E26: 0 | F26: nSCAYGTGhbb | G26: HOCOMOCOv11 | H26: ChIP-Seq | I26: 0.86415614 | J26: 0.87506917 | K26: 18 | L26: 15 | M26: 410 | N26: PAS domain factors{1.2.5} | O26: Arnt-like factors{1.2.5.2} | P26: 701 | Q26: 406 | R26: BMAL1_HUMAN | S26: O00327
A27: BRAC_HUMAN.H11MO.0.A | B27: T | C27: 20 | D27: A | E27: 0 | F27: bYvvMRdvnvdSTGWKARdd | G27: HOCOMOCOv11 | H27: ChIP-Seq | I27: 0.83523693 | J27: 0.81776072 | K27: 9 | L27: 10 | M27: 500 | N27: Brachyury-related factors{6.5.1} | O27: T (Brachyury){6.5.1.0.1} | P27: 11515 | Q27: 6862 | R27: BRAC_HUMAN | S27: O15178
A28: CDX1_HUMAN.H11MO.0.C | B28: CDX1 | C28: 8 | D28: C | E28: 0 | F28: hTTKAWGd | G28: HOCOMOCOv9 | H28: Integrative | M28: 30 | N28: HOX-related factors{3.1.1} | O28: CDX (Caudal type homeobox){3.1.1.9} | P28: 1805 | Q28: 1044 | R28: CDX1_HUMAN | S28: P47902
A29: CDX2_HUMAN.H11MO.0.A | B29: CDX2 | C29: 12 | D29: A | E29: 0 | F29: dTTbATKGShbY | G29: HOCOMOCOv11 | H29: ChIP-Seq | I29: 0.92304957 | J29: 0.98211674 | K29: 13 | L29: 23 | M29: 151 | N29: HOX-related factors{3.1.1} | O29: CDX (Caudal type homeobox){3.1.1.9} | P29: 1806 | Q29: 1045 | R29: CDX2_HUMAN | S29: Q99626
A30: CEBPA_HUMAN.H11MO.0.A | B30: CEBPA | C30: 12 | D30: A | E30: 0 | F30: dRTTKhGCAAYv | G30: HOCOMOCOv11 | H30: ChIP-Seq | I30: 0.98337589 | J30: 0.99050255 | K30: 18 | L30: 153 | M30: 500 | N30: C/EBP-related{1.1.8} | O30: C/EBP{1.1.8.1} | P30: 1833 | Q30: 1050 | R30: CEBPA_HUMAN | S30: P49715
A31: CEBPB_HUMAN.H11MO.0.A | B31: CEBPB | C31: 12 | D31: A | E31: 0 | F31: dRTTRhGCAAYv | G31: HOCOMOCOv11 | H31: ChIP-Seq | I31: 0.98145316 | J31: 0.98531043 | K31: 65 | L31: 158 | M31: 457 | N31: C/EBP-related{1.1.8} | O31: C/EBP{1.1.8.1} | P31: 1834 | Q31: 1051 | R31: CEBPB_HUMAN | S31: P17676
A32: CEBPD_HUMAN.H11MO.0.C | B32: CEBPD | C32: 11 | D32: C | E32: 0 | F32: vTTGCdYMAbh | G32: HOCOMOCOv11 | H32: ChIP-Seq | I32: 0.83078732 | K32: 10 | M32: 500 | N32: C/EBP-related{1.1.8} | O32: C/EBP{1.1.8.1} | P32: 1835 | Q32: 1052 | R32: CEBPD_HUMAN | S32: P49716
A33: CEBPE_HUMAN.H11MO.0.A | B33: CEBPE | C33: 12 | D33: A | E33: 0 | F33: dTKSGMAAThdb | G33: HOCOMOCOv9 | H33: Integrative | M33: 803 | N33: C/EBP-related{1.1.8} | O33: C/EBP{1.1.8.1} | P33: 1836 | Q33: 1053 | R33: CEBPE_HUMAN | S33: Q15744
A34: CEBPG_HUMAN.H11MO.0.B | B34: CEBPG | C34: 12 | D34: B | E34: 0 | F34: RTTRCATCAKhh | G34: HOCOMOCOv11 | H34: ChIP-Seq | I34: 0.73813043 | J34: 0.97173164 | K34: 2 | L34: 4 | M34: 501 | N34: C/EBP-related{1.1.8} | O34: C/EBP{1.1.8.1} | P34: 1837 | Q34: 1054 | R34: CEBPG_HUMAN | S34: P53567
A35: CLOCK_HUMAN.H11MO.0.C | B35: CLOCK | C35: 14 | D35: C | E35: 0 | F35: SdvnCAMRYGvvvh | G35: HOCOMOCOv11 | H35: ChIP-Seq | I35: 0.65821847 | J35: 0.73453481 | K35: 5 | L35: 22 | M35: 253 | N35: PAS domain factors{1.2.5} | O35: Arnt-like factors{1.2.5.2} | P35: 2082 | Q35: 9575 | R35: CLOCK_HUMAN | S35: O15516
A36: COE1_HUMAN.H11MO.0.A | B36: EBF1 | C36: 15 | D36: A | E36: 0 | F36: vdbYCCCMWGGGRvh | G36: HOCOMOCOv11 | H36: ChIP-Seq | I36: 0.99417685 | J36: 0.99219462 | K36: 17 | L36: 55 | M36: 500 | N36: Early B-Cell Factor-related factors{6.1.5} | O36: EBF1 (COE1){6.1.5.0.1} | P36: 3126 | Q36: 1879 | R36: COE1_HUMAN | S36: Q9UH73
A37: COT1_HUMAN.H11MO.0.C | B37: NR2F1 | C37: 17 | D37: C | E37: 0 | F37: vRRRbvRRAGGKCAdvv | G37: HOCOMOCOv11 | H37: ChIP-Seq | I37: 0.87928937 | K37: 3 | M37: 501 | N37: RXR-related receptors (NR2){2.1.3} | O37: COUP-like receptors (NR2F){2.1.3.5} | P37: 7975 | Q37: 7025 | R37: COT1_HUMAN | S37: P10589
A38: COT2_HUMAN.H11MO.0.A | B38: NR2F2 | C38: 13 | D38: A | E38: 0 | F38: vMRAGGTCAdvdd | G38: HOCOMOCOv10 | H38: ChIP-Seq | I38: 0.9337305 | J38: 0.83341543 | K38: 28 | L38: 3 | M38: 509 | N38: RXR-related receptors (NR2){2.1.3} | O38: COUP-like receptors (NR2F){2.1.3.5} | P38: 7976 | Q38: 7026 | R38: COT2_HUMAN | S38: P24468
A39: CREB1_HUMAN.H11MO.0.A | B39: CREB1 | C39: 11 | D39: A | E39: 0 | F39: ndRTGACGYhW | G39: HOCOMOCOv11 | H39: ChIP-Seq | I39: 0.92678774 | J39: 0.88827561 | K39: 63 | L39: 8 | M39: 501 | N39: CREB-related factors{1.1.7} | O39: CREB-like factors{1.1.7.1} | P39: 2345 | Q39: 1385 | R39: CREB1_HUMAN | S39: P16220
A40: CREM_HUMAN.H11MO.0.C | B40: CREM | C40: 11 | D40: C | E40: 0 | F40: SRvTGACGTSA | G40: HOCOMOCOv9 | H40: Integrative | M40: 30 | N40: CREB-related factors{1.1.7} | O40: CREB-like factors{1.1.7.1} | P40: 2352 | Q40: 1390 | R40: CREM_HUMAN | S40: Q03060
...
